Workbook

Sheet сравнение
T1: =CORREL(U:U,V:V) -> 0.020258565 | U1: 209.52881 | V1: 107.28158
U2: 234.92815 | V2: 127.82735
U3: 70.260556 | V3: 408.35467
U4: 369.86282 | V4: 98.890546
U5: 332.22945 | V5: 701.75958
U6: 130.66505 | V6: 271.81439
U7: 107.26249 | V7: 320.49549
U8: 304.89436 | V8: 248.02335
U9: 220.47323 | V9: 224.91195
U10: 681.11685 | V10: 454.21521
U11: 254.7299 | V11: 254.47078
U12: 235.08798 | V12: 216.90658
U13: 121.42863 | V13: 797.62537
... U23: 368.01975 | V23: 365.89968
A24: 24.13; 78.91 | B24: 78.91; 133.7 | C24: 133.7; 188.48 | D24: 188.48; 243.26 | E24: 243.26; 298.04 | F24: 298.04; 352.83 | G24: 352.83; 407.61 | H24: 407.61; 462.39 | I24: 462.39; 517.18 | J24: 517.18; 571.96 | K24: 571.96; 626.74 | L24: 626.74; 681.53 | M24: 681.53; 736.31 | N24: 736.31; 791.09 | O24: 791.09; 845.88 | P24: 845.88; 900.66 | Q24: 900.66; 955.44 | R24: 955.44; 1010.23 | U24: 259.37419 | V24: 126.08794
A25: 26 | B25: 36 | C25: 49 | D25: 39 | E25: 39 | F25: 25 | G25: 18 | H25: 19 | I25: 23 | J25: 8 | K25: 6 | L25: 3 | M25: 3 | N25: 3 | O25: 0 | P25: 0 | Q25: 1 | R25: 2 | U25: 164.98614 | V25: 158.17331
A26: 20.67; 84.81 | B26: 84.81; 148.96 | C26: 148.96; 213.1 | D26: 213.1; 277.25 | E26: 277.25; 341.39 | F26: 341.39; 405.53 | G26: 405.53; 469.68 | H26: 469.68; 533.82 | I26: 533.82; 597.96 | J26: 597.96; 662.11 | K26: 662.11; 726.25 | L26: 726.25; 790.4 | M26: 790.4; 854.54 | N26: 854.54; 918.68 | O26: 918.68; 982.83 | P26: 982.83; 1046.97 | Q26: 1046.97; 1111.11 | R26: 1111.11; 1175.26 | U26: 326.93469 | V26: 169.31815
A27: 25 | B27: 50 | C27: 55 | D27: 41 | E27: 40 | F27: 28 | G27: 22 | H27: 19 | I27: 6 | J27: 3 | K27: 4 | L27: 3 | M27: 1 | N27: 2 | O27: 0 | P27: 0 | Q27: 0 | R27: 1 | U27: 594.28892 | V27: 356.99176
U28: 67.642177 | V28: 51.531821
U29: 327.53881 | V29: 138.94007
A30: 1 | B30: 2 | C30: 3 | D30: 4 | E30: 5 | F30: 6 | G30: 7 | H30: 8 | I30: 9 | J30: 10 | K30: 11 | L30: 12 | M30: 13 | N30: 14 | O30: 15 | P30: 16 | Q30: 17 | R30: 18 | U30: 244.11186 | V30: 122.36436
A31: 25 | B31: 50 | C31: 55 | D31: 41 | E31: 40 | F31: 28 | G31: 22 | H31: 19 | I31: 6 | J31: 3 | K31: 4 | L31: 3 | M31: 1 | N31: 2 | O31: 0 | P31: 0 | Q31: 0 | R31: 1 | U31: 341.49191 | V31: 192.42386
A32: 26 | B32: 36 | C32: 49 | D32: 39 | E32: 39 | F32: 25 | G32: 18 | H32: 19 | I32: 23 | J32: 8 | K32: 6 | L32: 3 | M32: 3 | N32: 3 | O32: 0 | P32: 0 | Q32: 1 | R32: 2 | U32: 245.667 | V32: 314.19162
U33: 90.522744 | V33: 224.76624
U34: 372.04227 | V34: 55.898927
U35: 234.50838 | V35: 327.76712
U36: 271.38612 | V36: 375.33573
U37: 276.61619 | V37: 227.86162
U38: 305.02363 | V38: 355.13663
U39: 132.36814 | V39: 286.74132
U40: 315.68166 | V40: 133.99561
U41: 190.90806 | V41: 229.31356
U42: 169.4968 | V42: 427.57965
U43: 387.44213 | V43: 379.8838
U44: 482.23772 | V44: 470.07277
... U61: 52.658389 | V61: 527.20636
A62: 0.020994281 | B62: -0.01288353 | C62: -0.12895106 | D62: 0.030501461 | E62: -0.050425599 | F62: 0.036185478 | G62: -0.029315588 | H62: 0.023654263 | I62: -0.082337061 | J62: -0.071618304 | K62: -0.014472614 | L62: 0.043918925 | M62: -0.00065759763 | N62: -0.057710804 | O62: -0.070019005 | U62: 173.16219 | V62: 684.17142
A63: =A62-'300 ген'!$G$4 -> -278.91116 | B63: =B62-'300 ген'!$G$4 -> -278.94504 | C63: =C62-'300 ген'!$G$4 -> -279.0611 | D63: =D62-'300 ген'!$G$4 -> -278.90165 | E63: =E62-'300 ген'!$G$4 -> -278.98258 | F63: =F62-'300 ген'!$G$4 -> -278.89597 | G63: =G62-'300 ген'!$G$4 -> -278.96147 | H63: =H62-'300 ген'!$G$4 -> -278.9085 | ... O63: =O62-'300 ген'!$G$4 -> -279.00217 | P63: x - x ovel | U63: 252.11588 | V63: 318.45739
U64: 441.6448 | V64: 208.72149
A65: -0.031988355 | B65: -0.030426633 | C65: -0.049195743 | D65: 0.0042372883 | E65: 0.029058435 | F65: 0.068666816 | G65: 0.011581391 | H65: 0.058080889 | I65: 0.070174642 | J65: -0.041811579 | K65: 0.010879973 | L65: -0.0045146029 | M65: -0.024007168 | N65: -0.035223293 | O65: 0.0077740053 | U65: 47.848498 | V65: 246.93209
...

Sheet Лист1 ген
S1: =CORREL($Q$4:$Q$303,S4:S303) -> 0.020994281 | T1: =CORREL($Q$4:$Q$303,T4:T303) -> -0.01288353 | U1: =CORREL($Q$4:$Q$303,U4:U303) -> -0.12895106 | V1: =CORREL($Q$4:$Q$303,V4:V303) -> 0.030501461 | W1: =CORREL($Q$4:$Q$303,W4:W303) -> -0.050425599 | X1: =CORREL($Q$4:$Q$303,X4:X303) -> 0.036185478 | Y1: =CORREL($Q$4:$Q$303,Y4:Y303) -> -0.029315588 | Z1: =CORREL($Q$4:$Q$303,Z4:Z303) -> 0.023654263 | ... AG1: =CORREL($Q$4:$Q$303,AG4:AG303) -> -0.070019005 | AJ1: =AVERAGE(S1:AG1) -> -0.024209117
AJ2: =MEDIAN(S1:AG1) -> -0.014472614
R3: x - m | S3: 1 | T3: 2 | U3: 3 | V3: 4 | W3: 5 | X3: 6 | Y3: 7 | Z3: 8 | AA3: 9 | AB3: 10 | AC3: 11 | AD3: 12 | AE3: 13 | AF3: 14 | AG3: 15
A4: 209.52881 | Q4: 209.52881 | R4: =Q4-$F$30 -> -66.949391 | S4: =Q5 -> 234.92815 | T4: =S5 -> 70.260556 | U4: =T5 -> 369.86282 | V4: =U5 -> 332.22945 | W4: =V5 -> 130.66505 | X4: =W5 -> 107.26249 | Y4: =X5 -> 304.89436 | Z4: =Y5 -> 220.47323 | AA4: =Z5 -> 681.11685 | ... AG4: =AF5 -> 267.03747
A5: 234.92815 | Q5: 234.92815 | R5: =Q5-$F$30 -> -41.55005 | S5: =Q6 -> 70.260556 | T5: =S6 -> 369.86282 | U5: =T6 -> 332.22945 | V5: =U6 -> 130.66505 | W5: =V6 -> 107.26249 | X5: =W6 -> 304.89436 | Y5: =X6 -> 220.47323 | Z5: =Y6 -> 681.11685 | AA5: =Z6 -> 254.7299 | ... AG5: =AF6 -> 401.70769
A6: 70.260556 | Q6: 70.260556 | R6: =Q6-$F$30 -> -206.21765 | S6: =Q7 -> 369.86282 | T6: =S7 -> 332.22945 | U6: =T7 -> 130.66505 | V6: =U7 -> 107.26249 | W6: =V7 -> 304.89436 | X6: =W7 -> 220.47323 | Y6: =X7 -> 681.11685 | Z6: =Y7 -> 254.7299 | AA6: =Z7 -> 235.08798 | ... AG6: =AF7 -> 59.379924
A7: 369.86282 | Q7: 369.86282 | R7: =Q7-$F$30 -> 93.384615 | S7: =Q8 -> 332.22945 | T7: =S8 -> 130.66505 | U7: =T8 -> 107.26249 | V7: =U8 -> 304.89436 | W7: =V8 -> 220.47323 | X7: =W8 -> 681.11685 | Y7: =X8 -> 254.7299 | Z7: =Y8 -> 235.08798 | AA7: =Z8 -> 121.42863 | ... AG7: =AF8 -> 774.96764
A8: 332.22945 | Q8: 332.22945 | R8: =Q8-$F$30 -> 55.751252 | S8: =Q9 -> 130.66505 | T8: =S9 -> 107.26249 | U8: =T9 -> 304.89436 | V8: =U9 -> 220.47323 | W8: =V9 -> 681.11685 | X8: =W9 -> 254.7299 | Y8: =X9 -> 235.08798 | Z8: =Y9 -> 121.42863 | AA8: =Z9 -> 105.02894 | ... AG8: =AF9 -> 169.47109
A9: 130.66505 | Q9: 130.66505 | R9: =Q9-$F$30 -> -145.81316 | S9: =Q10 -> 107.26249 | T9: =S10 -> 304.89436 | U9: =T10 -> 220.47323 | V9: =U10 -> 681.11685 | W9: =V10 -> 254.7299 | X9: =W10 -> 235.08798 | Y9: =X10 -> 121.42863 | Z9: =Y10 -> 105.02894 | AA9: =Z10 -> 443.5748 | ... AG9: =AF10 -> 615.23665
A10: 107.26249 | Q10: 107.26249 | R10: =Q10-$F$30 -> -169.21571 | S10: =Q11 -> 304.89436 | T10: =S11 -> 220.47323 | U10: =T11 -> 681.11685 | V10: =U11 -> 254.7299 | W10: =V11 -> 235.08798 | X10: =W11 -> 121.42863 | Y10: =X11 -> 105.02894 | Z10: =Y11 -> 443.5748 | AA10: =Z11 -> 267.03747 | ... AG10: =AF11 -> 80.79866
A11: 304.89436 | Q11: 304.89436 | R11: =Q11-$F$30 -> 28.416158 | S11: =Q12 -> 220.47323 | T11: =S12 -> 681.11685 | U11: =T12 -> 254.7299 | V11: =U12 -> 235.08798 | W11: =V12 -> 121.42863 | X11: =W12 -> 105.02894 | Y11: =X12 -> 443.5748 | Z11: =Y12 -> 267.03747 | AA11: =Z12 -> 401.70769 | ... AG11: =AF12 -> 368.01975
A12: 220.47323 | Q12: 220.47323 | R12: =Q12-$F$30 -> -56.004968 | S12: =Q13 -> 681.11685 | T12: =S13 -> 254.7299 | U12: =T13 -> 235.08798 | V12: =U13 -> 121.42863 | W12: =V13 -> 105.02894 | X12: =W13 -> 443.5748 | Y12: =X13 -> 267.03747 | Z12: =Y13 -> 401.70769 | AA12: =Z13 -> 59.379924 | ... AG12: =AF13 -> 259.37419
A13: 681.11685 | Q13: 681.11685 | R13: =Q13-$F$30 -> 404.63865 | S13: =Q14 -> 254.7299 | T13: =S14 -> 235.08798 | U13: =T14 -> 121.42863 | V13: =U14 -> 105.02894 | W13: =V14 -> 443.5748 | X13: =W14 -> 267.03747 | Y13: =X14 -> 401.70769 | Z13: =Y14 -> 59.379924 | AA13: =Z14 -> 774.96764 | ... AG13: =AF14 -> 164.98614
A14: 254.7299 | Q14: 254.7299 | R14: =Q14-$F$30 -> -21.7483 | S14: =Q15 -> 235.08798 | T14: =S15 -> 121.42863 | U14: =T15 -> 105.02894 | V14: =U15 -> 443.5748 | W14: =V15 -> 267.03747 | X14: =W15 -> 401.70769 | Y14: =X15 -> 59.379924 | Z14: =Y15 -> 774.96764 | AA14: =Z15 -> 169.47109 | ... AG14: =AF15 -> 326.93469
A15: 235.08798 | Q15: 235.08798 | R15: =Q15-$F$30 -> -41.390218 | S15: =Q16 -> 121.42863 | T15: =S16 -> 105.02894 | U15: =T16 -> 443.5748 | V15: =U16 -> 267.03747 | W15: =V16 -> 401.70769 | X15: =W16 -> 59.379924 | Y15: =X16 -> 774.96764 | Z15: =Y16 -> 169.47109 | AA15: =Z16 -> 615.23665 | ... AG15: =AF16 -> 594.28892
... A27: 259.37419 | Q27: 259.37419 | R27: =Q27-$F$30 -> -17.104008 | S27: =Q28 -> 164.98614 | T27: =S28 -> 326.93469 | U27: =T28 -> 594.28892 | V27: =U28 -> 67.642177 | W27: =V28 -> 327.53881 | X27: =W28 -> 244.11186 | Y27: =X28 -> 341.49191 | Z27: =Y28 -> 245.667 | AA27: =Z28 -> 90.522744 | ... AG27: =AF28 -> 132.36814
A28: 164.98614 | E28: t_p | F28: 300 | Q28: 164.98614 | R28: =Q28-$F$30 -> -111.49206 | S28: =Q29 -> 326.93469 | T28: =S29 -> 594.28892 | U28: =T29 -> 67.642177 | V28: =U29 -> 327.53881 | W28: =V29 -> 244.11186 | X28: =W29 -> 341.49191 | Y28: =X29 -> 245.667 | Z28: =Y29 -> 90.522744 | AA28: =Z29 -> 372.04227 | ... AG28: =AF29 -> 315.68166
A29: 326.93469 | D29: кол-во | F29: 300 | Q29: 326.93469 | R29: =Q29-$F$30 -> 50.456484 | S29: =Q30 -> 594.28892 | T29: =S30 -> 67.642177 | U29: =T30 -> 327.53881 | V29: =U30 -> 244.11186 | W29: =V30 -> 341.49191 | X29: =W30 -> 245.667 | Y29: =X30 -> 90.522744 | Z29: =Y30 -> 372.04227 | AA29: =Z30 -> 234.50838 | ... AG29: =AF30 -> 190.90806
A30: 594.28892 | D30: мат ож | F30: 276.4782 | Q30: 594.28892 | R30: =Q30-$F$30 -> 317.81071 | S30: =Q31 -> 67.642177 | T30: =S31 -> 327.53881 | U30: =T31 -> 244.11186 | V30: =U31 -> 341.49191 | W30: =V31 -> 245.667 | X30: =W31 -> 90.522744 | Y30: =X31 -> 372.04227 | Z30: =Y31 -> 234.50838 | AA30: =Z31 -> 271.38612 | ... AG30: =AF31 -> 169.4968
A31: 67.642177 | D31: дисперсия | F31: 29298.173 | Q31: 67.642177 | R31: =Q31-$F$30 -> -208.83603 | S31: =Q32 -> 327.53881 | T31: =S32 -> 244.11186 | U31: =T32 -> 341.49191 | V31: =U32 -> 245.667 | W31: =V32 -> 90.522744 | X31: =W32 -> 372.04227 | Y31: =X32 -> 234.50838 | Z31: =Y32 -> 271.38612 | AA31: =Z32 -> 276.61619 | ... AG31: =AF32 -> 387.44213
A32: 327.53881 | D32: ср кв отклонение | F32: 171.16709 | Q32: 327.53881 | R32: =Q32-$F$30 -> 51.060604 | S32: =Q33 -> 244.11186 | T32: =S33 -> 341.49191 | U32: =T33 -> 245.667 | V32: =U33 -> 90.522744 | W32: =V33 -> 372.04227 | X32: =W33 -> 234.50838 | Y32: =X33 -> 271.38612 | Z32: =Y33 -> 276.61619 | AA32: =Z33 -> 305.02363 | ... AG32: =AF33 -> 482.23772
A33: 244.11186 | D33: коэфф вариации | F33: 0.61909796 | Q33: 244.11186 | R33: =Q33-$F$30 -> -32.366346 | S33: =Q34 -> 341.49191 | T33: =S34 -> 245.667 | U33: =T34 -> 90.522744 | V33: =U34 -> 372.04227 | W33: =V34 -> 234.50838 | X33: =W34 -> 271.38612 | Y33: =X34 -> 276.61619 | Z33: =Y34 -> 305.02363 | AA33: =Z34 -> 132.36814 | ... AG33: =AF34 -> 169.89721
A34: 341.49191 | C34: доверительный интервал | D34: 0.9 | E34: 1.684 | F34: 16.641855 | H34: 259.83635 | I34: < | J34: 276.4782 | K34: < | L34: 293.12006 | Q34: 341.49191 | R34: =Q34-$F$30 -> 65.013706 | S34: =Q35 -> 245.667 | T34: =S35 -> 90.522744 | U34: =T35 -> 372.04227 | V34: =U35 -> 234.50838 | W34: =V35 -> 271.38612 | X34: =W35 -> 276.61619 | Y34: =X35 -> 305.02363 | Z34: =Y35 -> 132.36814 | AA34: =Z35 -> 315.68166 | ... AG34: =AF35 -> 169.24971
A35: 245.667 | D35: 0.95 | E35: 1.96 | F35: 19.36938 | H35: 257.10882 | I35: < | J35: 276.4782 | K35: < | L35: 295.84758 | Q35: 245.667 | R35: =Q35-$F$30 -> -30.811206 | S35: =Q36 -> 90.522744 | T35: =S36 -> 372.04227 | U35: =T36 -> 234.50838 | V35: =U36 -> 271.38612 | W35: =V36 -> 276.61619 | X35: =W36 -> 305.02363 | Y35: =X36 -> 132.36814 | Z35: =Y36 -> 315.68166 | AA35: =Z36 -> 190.90806 | ... AG35: =AF36 -> 157.80896
A36: 90.522744 | D36: 0.99 | E36: 3.29 | F36: 32.512887 | H36: 243.96531 | I36: < | J36: 276.4782 | K36: < | L36: 308.99109 | Q36: 90.522744 | R36: =Q36-$F$30 -> -185.95546 | S36: =Q37 -> 372.04227 | T36: =S37 -> 234.50838 | U36: =T37 -> 271.38612 | V36: =U37 -> 276.61619 | W36: =V37 -> 305.02363 | X36: =W37 -> 132.36814 | Y36: =X37 -> 315.68166 | Z36: =Y37 -> 190.90806 | AA36: =Z37 -> 169.4968 | ... AG36: =AF37 -> 234.48901
A37: 372.04227 | D37: относ отклонение (относ 300) | Q37: 372.04227 | R37: =Q37-$F$30 -> 95.564072 | S37: =Q38 -> 234.50838 | T37: =S38 -> 271.38612 | U37: =T38 -> 276.61619 | V37: =U38 -> 305.02363 | W37: =V38 -> 132.36814 | X37: =W38 -> 315.68166 | Y37: =X38 -> 190.90806 | Z37: =Y38 -> 169.4968 | AA37: =Z38 -> 387.44213 | ... AG37: =AF38 -> 223.62842
A38: 234.50838 | Q38: 234.50838 | R38: =Q38-$F$30 -> -41.969821 | S38: =Q39 -> 271.38612 | T38: =S39 -> 276.61619 | U38: =T39 -> 305.02363 | V38: =U39 -> 132.36814 | W38: =V39 -> 315.68166 | X38: =W39 -> 190.90806 | Y38: =X39 -> 169.4968 | Z38: =Y39 -> 387.44213 | AA38: =Z39 -> 482.23772 | ... AG38: =AF39 -> 144.59081
A39: 271.38612 | D39: sigma_m | F39: 9.8823366 | Q39: 271.38612 | R39: =Q39-$F$30 -> -5.0920806 | S39: =Q40 -> 276.61619 | T39: =S40 -> 305.02363 | U39: =T40 -> 132.36814 | V39: =U40 -> 315.68166 | W39: =V40 -> 190.90806 | X39: =W40 -> 169.4968 | Y39: =X40 -> 387.44213 | Z39: =Y40 -> 482.23772 | AA39: =Z40 -> 169.89721 | ... AG39: =AF40 -> 538.78788
A40: 276.61619 | Q40: 276.61619 | R40: =Q40-$F$30 -> 0.13798802 | S40: =Q41 -> 305.02363 | T40: =S41 -> 132.36814 | U40: =T41 -> 315.68166 | V40: =U41 -> 190.90806 | W40: =V41 -> 169.4968 | X40: =W41 -> 387.44213 | Y40: =X41 -> 482.23772 | Z40: =Y41 -> 169.89721 | AA40: =Z41 -> 169.24971 | ... AG40: =AF41 -> 268.5154
A41: 305.02363 | Q41: 305.02363 | R41: =Q41-$F$30 -> 28.545427 | S41: =Q42 -> 132.36814 | T41: =S42 -> 315.68166 | U41: =T42 -> 190.90806 | V41: =U42 -> 169.4968 | W41: =V42 -> 387.44213 | X41: =W42 -> 482.23772 | Y41: =X42 -> 169.89721 | Z41: =Y42 -> 169.24971 | AA41: =Z42 -> 157.80896 | ... AG41: =AF42 -> 486.3661
A42: 132.36814 | Q42: 132.36814 | R42: =Q42-$F$30 -> -144.11006 | S42: =Q43 -> 315.68166 | T42: =S43 -> 190.90806 | U42: =T43 -> 169.4968 | V42: =U43 -> 387.44213 | W42: =V43 -> 482.23772 | X42: =W43 -> 169.89721 | Y42: =X43 -> 169.24971 | Z42: =Y43 -> 157.80896 | AA42: =Z43 -> 234.48901 | ... AG42: =AF43 -> 280.20437
A43: 315.68166 | Q43: 315.68166 | R43: =Q43-$F$30 -> 39.203453 | S43: =Q44 -> 190.90806 | T43: =S44 -> 169.4968 | U43: =T44 -> 387.44213 | V43: =U44 -> 482.23772 | W43: =V44 -> 169.89721 | X43: =W44 -> 169.24971 | Y43: =X44 -> 157.80896 | Z43: =Y44 -> 234.48901 | AA43: =Z44 -> 223.62842 | ... AG43: =AF44 -> 467.16074
A44: 190.90806 | Q44: 190.90806 | R44: =Q44-$F$30 -> -85.570146 | S44: =Q45 -> 169.4968 | T44: =S45 -> 387.44213 | U44: =T45 -> 482.23772 | V44: =U45 -> 169.89721 | W44: =V45 -> 169.24971 | X44: =W45 -> 157.80896 | Y44: =X45 -> 234.48901 | Z44: =Y45 -> 223.62842 | AA44: =Z45 -> 144.59081 | ... AG44: =AF45 -> 163.15559
A45: 169.4968 | Q45: 169.4968 | R45: =Q45-$F$30 -> -106.9814 | S45: =Q46 -> 387.44213 | T45: =S46 -> 482.23772 | U45: =T46 -> 169.89721 | V45: =U46 -> 169.24971 | W45: =V46 -> 157.80896 | X45: =W46 -> 234.48901 | Y45: =X46 -> 223.62842 | Z45: =Y46 -> 144.59081 | AA45: =Z46 -> 538.78788 | ... AG45: =AF46 -> 504.1307
A46: 387.44213 | Q46: 387.44213 | R46: =Q46-$F$30 -> 110.96393 | S46: =Q47 -> 482.23772 | T46: =S47 -> 169.89721 | U46: =T47 -> 169.24971 | V46: =U47 -> 157.80896 | W46: =V47 -> 234.48901 | X46: =W47 -> 223.62842 | Y46: =X47 -> 144.59081 | Z46: =Y47 -> 538.78788 | AA46: =Z47 -> 268.5154 | ... AG46: =AF47 -> 434.01183
A47: 482.23772 | Q47: 482.23772 | R47: =Q47-$F$30 -> 205.75952 | S47: =Q48 -> 169.89721 | T47: =S48 -> 169.24971 | U47: =T48 -> 157.80896 | V47: =U48 -> 234.48901 | W47: =V48 -> 223.62842 | X47: =W48 -> 144.59081 | Y47: =X48 -> 538.78788 | Z47: =Y48 -> 268.5154 | AA47: =Z48 -> 486.3661 | ... AG47: =AF48 -> 488.9939
A48: 169.89721 | Q48: 169.89721 | R48: =Q48-$F$30 -> -106.58099 | S48: =Q49 -> 169.24971 | T48: =S49 -> 157.80896 | U48: =T49 -> 234.48901 | V48: =U49 -> 223.62842 | W48: =V49 -> 144.59081 | X48: =W49 -> 538.78788 | Y48: =X49 -> 268.5154 | Z48: =Y49 -> 486.3661 | AA48: =Z49 -> 280.20437 | ... AG48: =AF49 -> 166.78356
A49: 169.24971 | Q49: 169.24971 | R49: =Q49-$F$30 -> -107.2285 | S49: =Q50 -> 157.80896 | T49: =S50 -> 234.48901 | U49: =T50 -> 223.62842 | V49: =U50 -> 144.59081 | W49: =V50 -> 538.78788 | X49: =W50 -> 268.5154 | Y49: =X50 -> 486.3661 | Z49: =Y50 -> 280.20437 | AA49: =Z50 -> 467.16074 | ... AG49: =AF50 -> 52.658389
A50: 157.80896 | Q50: 157.80896 | R50: =Q50-$F$30 -> -118.66924 | S50: =Q51 -> 234.48901 | T50: =S51 -> 223.62842 | U50: =T51 -> 144.59081 | V50: =U51 -> 538.78788 | W50: =V51 -> 268.5154 | X50: =W51 -> 486.3661 | Y50: =X51 -> 280.20437 | Z50: =Y51 -> 467.16074 | AA50: =Z51 -> 163.15559 | ... AG50: =AF51 -> 173.16219
A51: 234.48901 | Q51: 234.48901 | R51: =Q51-$F$30 -> -41.989196 | S51: =Q52 -> 223.62842 | T51: =S52 -> 144.59081 | U51: =T52 -> 538.78788 | V51: =U52 -> 268.5154 | W51: =V52 -> 486.3661 | X51: =W52 -> 280.20437 | Y51: =X52 -> 467.16074 | Z51: =Y52 -> 163.15559 | AA51: =Z52 -> 504.1307 | ... AG51: =AF52 -> 252.11588
...

Sheet 10 ген
B1: x - m_volna ^ 2
A2: 209.52881 | B2: =(A2-$G$4)*(A2-$G$4) -> 3202.8092 | F2: t_p | G2: 10 | O2: Отклонение от эталона
A3: 234.92815 | B3: =(A3-$G$4)*(A3-$G$4) -> 973.0672 | E3: кол-во | G3: =COUNT(A2:A11) -> 10
A4: 70.260556 | B4: =(A4-$G$4)*(A4-$G$4) -> 38361.775 | E4: мат ож | G4: =SUM(A2:A11)/G2 -> 266.12218 | O4: =(P4-G4)/G4 -> 0.11361411 | P4: ='10'!G4 -> 296.35741
A5: 369.86282 | B5: =(A5-$G$4)*(A5-$G$4) -> 10762.12 | E5: дисперсия | G5: =SUM(B2:B11)/(G2-1) -> 30784.741 | O5: =(P5-G5)/G5 -> 0.13181701 | P5: ='10'!G5 -> 34842.693
A6: 332.22945 | B6: =(A6-$G$4)*(A6-$G$4) -> 4370.172 | E6: ср кв отклонение | G6: =SQRT(G5) -> 175.45581 | O6: =(P6-G6)/G6 -> 0.063868889 | P6: ='10'!G6 -> 186.66198
A7: 130.66505 | B7: =(A7-$G$4)*(A7-$G$4) -> 18348.635 | E7: коэфф вариации | G7: =G6/G4 -> 0.65930547 | O7: =(P7-G7)/G7 -> -0.044670074 | P7: ='10'!G7 -> 0.62985425
A8: 107.26249 | B8: =(A8-$G$4)*(A8-$G$4) -> 25236.399 | D8: доверительный интервал | E8: 0.9 | F8: 1.684 | G8: =$G$13*F8 -> 93.435053 | I8: =K8-G8 -> 172.68712 | J8: < | K8: =$G$4 -> 266.12218 | L8: < | M8: =K8+G8 -> 359.55723 | O8: =(P8-G8)/G8 -> 0.063868889 | P8: ='10'!G8 -> 99.402646
A9: 304.89436 | B9: =(A9-$G$4)*(A9-$G$4) -> 1503.2821 | E9: 0.95 | F9: 1.96 | G9: =$G$13*F9 -> 108.74864 | I9: =K9-G9 -> 157.37354 | J9: < | K9: =$G$4 -> 266.12218 | L9: < | M9: =K9+G9 -> 374.87081 | O9: =(P9-G9)/G9 -> 0.063868889 | P9: ='10'!G9 -> 115.69429
A10: 220.47323 | B10: =(A10-$G$4)*(A10-$G$4) -> 2083.826 | E10: 0.99 | F10: 2.579 | G10: =$G$13*F10 -> 143.09323 | I10: =K10-G10 -> 123.02895 | J10: < | K10: =$G$4 -> 266.12218 | L10: < | M10: =K10+G10 -> 409.21541 | O10: =(P10-G10)/G10 -> 0.063868889 | P10: ='10'!G10 -> 152.23244
A11: 681.11685 | B11: =(A11-$G$4)*(A11-$G$4) -> 172220.58 | E11: относ отклонение (относ 300)
E13: sigma_m | G13: =SQRT(G5/G2) -> 55.483998

Sheet 20 ген
C1: x - m_volna ^ 2
A2: 209.52881 | B2: =(A2-$G$4)*(A2-$G$4) -> 4244.911 | F2: t_p | G2: 20 | O2: Отклонение от эталона
A3: 234.92815 | B3: =(A3-$G$4)*(A3-$G$4) -> 1580.3519 | E3: кол-во | G3: =COUNT(A:A) -> 20
A4: 70.260556 | B4: =(A4-$G$4)*(A4-$G$4) -> 41788.042 | E4: мат ож | G4: =SUM(A:A)/G2 -> 274.68179 | O4: =(P4-G4)/G4 -> 0.123366 | P4: ='20'!G4 -> 308.56819
A5: 369.86282 | B5: =(A5-$G$4)*(A5-$G$4) -> 9059.4275 | E5: дисперсия | G5: =SUM(B:B)/(G2-1) -> 36024.141 | O5: =(P5-G5)/G5 -> 0.14394855 | P5: ='20'!G5 -> 41209.764
A6: 332.22945 | B6: =(A6-$G$4)*(A6-$G$4) -> 3311.7333 | E6: ср кв отклонение | G6: =SQRT(G5) -> 189.80027 | O6: =(P6-G6)/G6 -> 0.069555305 | P6: ='20'!G6 -> 203.00188
A7: 130.66505 | B7: =(A7-$G$4)*(A7-$G$4) -> 20740.823 | E7: коэфф вариации | G7: =G6/G4 -> 0.69098233 | O7: =(P7-G7)/G7 -> -0.047901304 | P7: ='20'!G7 -> 0.65788338
A8: 107.26249 | B8: =(A8-$G$4)*(A8-$G$4) -> 28029.222 | D8: доверительный интервал | E8: 0.9 | F8: 1.684 | G8: =$G$13*F8 -> 71.470021 | I8: =K8-G8 -> 203.21177 | J8: < | K8: =$G$4 -> 274.68179 | L8: < | M8: =K8+G8 -> 346.15181 | O8: =(P8-G8)/G8 -> 0.069555305 | P8: ='20'!G8 -> 76.44114
A9: 304.89436 | B9: =(A9-$G$4)*(A9-$G$4) -> 912.79927 | E9: 0.95 | F9: 1.96 | G9: =$G$13*F9 -> 83.183634 | I9: =K9-G9 -> 191.49816 | J9: < | K9: =$G$4 -> 274.68179 | L9: < | M9: =K9+G9 -> 357.86543 | O9: =(P9-G9)/G9 -> 0.069555305 | P9: ='20'!G9 -> 88.969497
A10: 220.47323 | B10: =(A10-$G$4)*(A10-$G$4) -> 2938.5677 | E10: 0.99 | F10: 2.579 | G10: =$G$13*F10 -> 109.45438 | I10: =K10-G10 -> 165.22741 | J10: < | K10: =$G$4 -> 274.68179 | L10: < | M10: =K10+G10 -> 384.13618 | O10: =(P10-G10)/G10 -> 0.069555305 | P10: ='20'!G10 -> 117.06752
A11: 681.11685 | B11: =(A11-$G$4)*(A11-$G$4) -> 165189.46 | E11: относ отклонение (относ 300)
A12: 254.7299 | B12: =(A12-$G$4)*(A12-$G$4) -> 398.07791
A13: 235.08798 | B13: =(A13-$G$4)*(A13-$G$4) -> 1567.6696 | E13: sigma_m | G13: =SQRT(G5/G2) -> 42.44063
A14: 121.42863 | B14: =(A14-$G$4)*(A14-$G$4) -> 23486.532
A15: 105.02894 | B15: =(A15-$G$4)*(A15-$G$4) -> 28782.09
A16: 443.5748 | B16: =(A16-$G$4)*(A16-$G$4) -> 28524.848
A17: 267.03747 | B17: =(A17-$G$4)*(A17-$G$4) -> 58.435671
A18: 401.70769 | B18: =(A18-$G$4)*(A18-$G$4) -> 16135.58
A19: 59.379924 | B19: =(A19-$G$4)*(A19-$G$4) -> 46354.894
A20: 774.96764 | B20: =(A20-$G$4)*(A20-$G$4) -> 250285.92
A21: 169.47109 | B21: =(A21-$G$4)*(A21-$G$4) -> 11069.292

Sheet 50 ген
C1: x - m_volna ^ 2
A2: 209.52881 | B2: =(A2-$G$4)*(A2-$G$4) -> 3554.9832 | F2: t_p | G2: 50 | O2: Отклонение от эталона
A3: 234.92815 | B3: =(A3-$G$4)*(A3-$G$4) -> 1171.3053 | E3: кол-во | G3: =COUNT(A:A) -> 50
A4: 70.260556 | B4: =(A4-$G$4)*(A4-$G$4) -> 39558.002 | E4: мат ож | G4: =SUM(A:A)/G2 -> 269.15249 | O4: =(P4-G4)/G4 -> 0.0098953157 | P4: ='50'!G4 -> 271.81584
A5: 369.86282 | B5: =(A5-$G$4)*(A5-$G$4) -> 10142.57 | E5: дисперсия | G5: =SUM(B:B)/(G2-1) -> 24753.261 | O5: =(P5-G5)/G5 -> 0.01657979 | P5: ='50'!G5 -> 25163.665
A6: 332.22945 | B6: =(A6-$G$4)*(A6-$G$4) -> 3978.7032 | E6: ср кв отклонение | G6: =SQRT(G5) -> 157.33169 | O6: =(P6-G6)/G6 -> 0.0082558158 | P6: ='50'!G6 -> 158.63059
A7: 130.66505 | B7: =(A7-$G$4)*(A7-$G$4) -> 19178.772 | E7: коэфф вариации | G7: =G6/G4 -> 0.58454481 | O7: =(P7-G7)/G7 -> -0.0016234354 | P7: ='50'!G7 -> 0.58359584
A8: 107.26249 | B8: =(A8-$G$4)*(A8-$G$4) -> 26208.372 | D8: доверительный интервал | E8: 0.9 | F8: 1.684 | G8: =$G$13*F8 -> 37.469103 | I8: =K8-G8 -> 231.68339 | J8: < | K8: =$G$4 -> 269.15249 | L8: < | M8: =K8+G8 -> 306.62159 | O8: =(P8-G8)/G8 -> 0.0082558158 | P8: ='50'!G8 -> 37.778441
A9: 304.89436 | B9: =(A9-$G$4)*(A9-$G$4) -> 1277.4812 | E9: 0.95 | F9: 1.96 | G9: =$G$13*F9 -> 43.61012 | I9: =K9-G9 -> 225.54237 | J9: < | K9: =$G$4 -> 269.15249 | L9: < | M9: =K9+G9 -> 312.76261 | O9: =(P9-G9)/G9 -> 0.0082558158 | P9: ='50'!G9 -> 43.970157
A10: 220.47323 | B10: =(A10-$G$4)*(A10-$G$4) -> 2369.67 | E10: 0.99 | F10: 2.579 | G10: =$G$13*F10 -> 57.382908 | I10: =K10-G10 -> 211.76958 | J10: < | K10: =$G$4 -> 269.15249 | L10: < | M10: =K10+G10 -> 326.5354 | O10: =(P10-G10)/G10 -> 0.0082558158 | P10: ='50'!G10 -> 57.856651
A11: 681.11685 | B11: =(A11-$G$4)*(A11-$G$4) -> 169714.64 | E11: относ отклонение (относ 300)
A12: 254.7299 | B12: =(A12-$G$4)*(A12-$G$4) -> 208.01106
A13: 235.08798 | B13: =(A13-$G$4)*(A13-$G$4) -> 1160.3906 | E13: sigma_m | G13: =SQRT(G5/G2) -> 22.250061
A14: 121.42863 | B14: =(A14-$G$4)*(A14-$G$4) -> 21822.339
A15: 105.02894 | B15: =(A15-$G$4)*(A15-$G$4) -> 26936.539
A16: 443.5748 | B16: =(A16-$G$4)*(A16-$G$4) -> 30423.141
A17: 267.03747 | B17: =(A17-$G$4)*(A17-$G$4) -> 4.4733158
A18: 401.70769 | B18: =(A18-$G$4)*(A18-$G$4) -> 17570.882
A19: 59.379924 | B19: =(A19-$G$4)*(A19-$G$4) -> 44004.53
A20: 774.96764 | B20: =(A20-$G$4)*(A20-$G$4) -> 255848.96
A21: 169.47109 | B21: =(A21-$G$4)*(A21-$G$4) -> 9936.382
A22: 615.23665 | B22: =(A22-$G$4)*(A22-$G$4) -> 119774.24
A23: 80.79866 | B23: =(A23-$G$4)*(A23-$G$4) -> 35477.166
A24: 368.01975 | B24: =(A24-$G$4)*(A24-$G$4) -> 9774.7358
A25: 259.37419 | B25: =(A25-$G$4)*(A25-$G$4) -> 95.61508
... A51: 144.59081 | B51: =(A51-$G$4)*(A51-$G$4) -> 15515.611

Sheet 100 ген
C1: x - m_volna ^ 2
A2: 209.52881 | B2: =(A2-$G$4)*(A2-$G$4) -> 3683.7512 | F2: t_p | G2: =G3 -> 100 | O2: Отклонение от эталона
A3: 234.92815 | B3: =(A3-$G$4)*(A3-$G$4) -> 1245.7068 | E3: кол-во | G3: =COUNT(A:A) -> 100
A4: 70.260556 | B4: =(A4-$G$4)*(A4-$G$4) -> 39984.869 | E4: мат ож | G4: =SUM(A:A)/G2 -> 270.22272 | O4: =(P4-G4)/G4 -> 0.024863882 | P4: ='100'!G4 -> 276.94151
A5: 369.86282 | B5: =(A5-$G$4)*(A5-$G$4) -> 9928.148 | E5: дисперсия | G5: =SUM(B:B)/(G2-1) -> 29793.645 | O5: =(P5-G5)/G5 -> -0.12874273 | P5: ='100'!G5 -> 25957.93
A6: 332.22945 | B6: =(A6-$G$4)*(A6-$G$4) -> 3844.8344 | E6: ср кв отклонение | G6: =SQRT(G5) -> 172.60836 | O6: =(P6-G6)/G6 -> -0.066588372 | P6: ='100'!G6 -> 161.11465
A7: 130.66505 | B7: =(A7-$G$4)*(A7-$G$4) -> 19476.346 | E7: коэфф вариации | G7: =G6/G4 -> 0.6387633 | O7: =(P7-G7)/G7 -> -0.089233561 | P7: ='100'!G7 -> 0.58176417
A8: 107.26249 | B8: =(A8-$G$4)*(A8-$G$4) -> 26556.037 | D8: доверительный интервал | E8: 0.9 | F8: 1.684 | G8: =$G$13*F8 -> 29.067248 | I8: =K8-G8 -> 241.15548 | J8: < | K8: =$G$4 -> 270.22272 | L8: < | M8: =K8+G8 -> 299.28997 | O8: =(P8-G8)/G8 -> -0.066588372 | P8: ='100'!G8 -> 27.131707
A9: 304.89436 | B9: =(A9-$G$4)*(A9-$G$4) -> 1202.1223 | E9: 0.95 | F9: 1.96 | G9: =$G$13*F9 -> 33.831238 | I9: =K9-G9 -> 236.39149 | J9: < | K9: =$G$4 -> 270.22272 | L9: < | M9: =K9+G9 -> 304.05396 | O9: =(P9-G9)/G9 -> -0.066588372 | P9: ='100'!G9 -> 31.578471
A10: 220.47323 | B10: =(A10-$G$4)*(A10-$G$4) -> 2475.0118 | E10: 0.99 | F10: 2.579 | G10: =$G$13*F10 -> 44.515696 | I10: =K10-G10 -> 225.70703 | J10: < | K10: =$G$4 -> 270.22272 | L10: < | M10: =K10+G10 -> 314.73842 | O10: =(P10-G10)/G10 -> -0.066588372 | P10: ='100'!G10 -> 41.551468
A11: 681.11685 | B11: =(A11-$G$4)*(A11-$G$4) -> 168833.99 | E11: относ отклонение (относ 300)
A12: 254.7299 | B12: =(A12-$G$4)*(A12-$G$4) -> 240.02754
A13: 235.08798 | B13: =(A13-$G$4)*(A13-$G$4) -> 1234.45 | E13: sigma_m | G13: =SQRT(G5/G2) -> 17.260836
A14: 121.42863 | B14: =(A14-$G$4)*(A14-$G$4) -> 22139.683
A15: 105.02894 | B15: =(A15-$G$4)*(A15-$G$4) -> 27288.986
A16: 443.5748 | B16: =(A16-$G$4)*(A16-$G$4) -> 30050.942
A17: 267.03747 | B17: =(A17-$G$4)*(A17-$G$4) -> 10.145851
A18: 401.70769 | B18: =(A18-$G$4)*(A18-$G$4) -> 17288.297
A19: 59.379924 | B19: =(A19-$G$4)*(A19-$G$4) -> 44454.687
A20: 774.96764 | B20: =(A20-$G$4)*(A20-$G$4) -> 254767.42
A21: 169.47109 | B21: =(A21-$G$4)*(A21-$G$4) -> 10150.892
A22: 615.23665 | B22: =(A22-$G$4)*(A22-$G$4) -> 119034.61
A23: 80.79866 | B23: =(A23-$G$4)*(A23-$G$4) -> 35881.476
A24: 368.01975 | B24: =(A24-$G$4)*(A24-$G$4) -> 9564.259
A25: 259.37419 | B25: =(A25-$G$4)*(A25-$G$4) -> 117.69061
... A101: 321.74951 | B101: =(A101-$G$4)*(A101-$G$4) -> 2655.0094

Sheet 200 ген
C1: x - m_volna ^ 2
A2: 209.52881 | B2: =(A2-$G$4)*(A2-$G$4) -> 5010.4236 | F2: t_p | G2: =G3 -> 200 | O2: Отклонение от эталона
A3: 234.92815 | B3: =(A3-$G$4)*(A3-$G$4) -> 2059.7986 | E3: кол-во | G3: =COUNT(A:A) -> 200
A4: 70.260556 | B4: =(A4-$G$4)*(A4-$G$4) -> 44122.095 | E4: мат ож | G4: =SUM(A:A)/G2 -> 280.31316 | O4: =(P4-G4)/G4 -> -0.054312747 | P4: ='200'!G4 -> 265.08858
A5: 369.86282 | B5: =(A5-$G$4)*(A5-$G$4) -> 8019.1417 | E5: дисперсия | G5: =SUM(B:B)/(G2-1) -> 29658.102 | O5: =(P5-G5)/G5 -> -0.16134714 | P5: ='200'!G5 -> 24872.852
A6: 332.22945 | B6: =(A6-$G$4)*(A6-$G$4) -> 2695.3019 | E6: ср кв отклонение | G6: =SQRT(G5) -> 172.21528 | O6: =(P6-G6)/G6 -> -0.084220081 | P6: ='200'!G6 -> 157.71129
A7: 130.66505 | B7: =(A7-$G$4)*(A7-$G$4) -> 22394.557 | E7: коэфф вариации | G7: =G6/G4 -> 0.61436744 | O7: =(P7-G7)/G7 -> -0.031624973 | P7: ='200'!G7 -> 0.59493809
A8: 107.26249 | B8: =(A8-$G$4)*(A8-$G$4) -> 29946.532 | D8: доверительный интервал | E8: 0.9 | F8: 1.684 | G8: =$G$13*F8 -> 20.506841 | I8: =K8-G8 -> 259.80632 | J8: < | K8: =$G$4 -> 280.31316 | L8: < | M8: =K8+G8 -> 300.82 | O8: =(P8-G8)/G8 -> -0.084220081 | P8: ='200'!G8 -> 18.779753
A9: 304.89436 | B9: =(A9-$G$4)*(A9-$G$4) -> 604.23557 | E9: 0.95 | F9: 1.96 | G9: =$G$13*F9 -> 23.86782 | I9: =K9-G9 -> 256.44534 | J9: < | K9: =$G$4 -> 280.31316 | L9: < | M9: =K9+G9 -> 304.18098 | O9: =(P9-G9)/G9 -> -0.084220081 | P9: ='200'!G9 -> 21.85767
A10: 220.47323 | B10: =(A10-$G$4)*(A10-$G$4) -> 3580.8163 | E10: 0.99 | F10: 2.579 | G10: =$G$13*F10 -> 31.405667 | I10: =K10-G10 -> 248.90749 | J10: < | K10: =$G$4 -> 280.31316 | L10: < | M10: =K10+G10 -> 311.71882 | O10: =(P10-G10)/G10 -> -0.084220081 | P10: ='200'!G10 -> 28.760679
A11: 681.11685 | B11: =(A11-$G$4)*(A11-$G$4) -> 160643.6 | E11: относ отклонение (относ 300)
A12: 254.7299 | B12: =(A12-$G$4)*(A12-$G$4) -> 654.5029
A13: 235.08798 | B13: =(A13-$G$4)*(A13-$G$4) -> 2045.3162 | E13: sigma_m | G13: =SQRT(G5/G2) -> 12.177459
A14: 121.42863 | B14: =(A14-$G$4)*(A14-$G$4) -> 25244.293
A15: 105.02894 | B15: =(A15-$G$4)*(A15-$G$4) -> 30724.556
A16: 443.5748 | B16: =(A16-$G$4)*(A16-$G$4) -> 26654.364
A17: 267.03747 | B17: =(A17-$G$4)*(A17-$G$4) -> 176.24387
A18: 401.70769 | B18: =(A18-$G$4)*(A18-$G$4) -> 14736.634
A19: 59.379924 | B19: =(A19-$G$4)*(A19-$G$4) -> 48811.493
A20: 774.96764 | B20: =(A20-$G$4)*(A20-$G$4) -> 244683.05
A21: 169.47109 | B21: =(A21-$G$4)*(A21-$G$4) -> 12285.964
A22: 615.23665 | B22: =(A22-$G$4)*(A22-$G$4) -> 112173.74
A23: 80.79866 | B23: =(A23-$G$4)*(A23-$G$4) -> 39806.034
A24: 368.01975 | B24: =(A24-$G$4)*(A24-$G$4) -> 7692.4473
A25: 259.37419 | B25: =(A25-$G$4)*(A25-$G$4) -> 438.44013
... A201: 364.09254 | B201: =(A201-$G$4)*(A201-$G$4) -> 7018.9849

Sheet 300 ген
C1: x - m_volna ^ 2
A2: 209.52881 | B2: =(A2-$G$4)*(A2-$G$4) -> 4816.824 | F2: t_p | G2: =G3 -> 300 | O2: Отклонение от эталона
A3: 234.92815 | B3: =(A3-$G$4)*(A3-$G$4) -> 1936.3521 | E3: кол-во | G3: =COUNT(A:A) -> 300
A4: 70.260556 | B4: =(A4-$G$4)*(A4-$G$4) -> 43543.836 | E4: мат ож | G4: =SUM(A:A)/G2 -> 278.93215 | O4: =(P4-G4)/G4 -> -0.0087976645 | P4: ='300'!G4 -> 276.4782
A5: 369.86282 | B5: =(A5-$G$4)*(A5-$G$4) -> 8268.3856 | E5: дисперсия | G5: =SUM(B:B)/(G2-1) -> 30843.424 | O5: =(P5-G5)/G5 -> -0.050099853 | P5: ='300'!G5 -> 29298.173
A6: 332.22945 | B6: =(A6-$G$4)*(A6-$G$4) -> 2840.6022 | E6: ср кв отклонение | G6: =SQRT(G5) -> 175.62296 | O6: =(P6-G6)/G6 -> -0.02537179 | P6: ='300'!G6 -> 171.16709
A7: 130.66505 | B7: =(A7-$G$4)*(A7-$G$4) -> 21983.135 | E7: коэфф вариации | G7: =G6/G4 -> 0.62962608 | O7: =(P7-G7)/G7 -> -0.016721234 | P7: ='300'!G7 -> 0.61909796
A8: 107.26249 | B8: =(A8-$G$4)*(A8-$G$4) -> 29470.472 | D8: доверительный интервал | E8: 0.9 | F8: 1.684 | G8: =$G$13*F8 -> 17.07508 | I8: =K8-G8 -> 261.85707 | J8: < | K8: =$G$4 -> 278.93215 | L8: < | M8: =K8+G8 -> 296.00723 | O8: =(P8-G8)/G8 -> -0.02537179 | P8: ='300'!G8 -> 16.641855
A9: 304.89436 | B9: =(A9-$G$4)*(A9-$G$4) -> 674.03617 | E9: 0.95 | F9: 1.96 | G9: =$G$13*F9 -> 19.873609 | I9: =K9-G9 -> 259.05855 | J9: < | K9: =$G$4 -> 278.93215 | L9: < | M9: =K9+G9 -> 298.80576 | O9: =(P9-G9)/G9 -> -0.02537179 | P9: ='300'!G9 -> 19.36938
A10: 220.47323 | B10: =(A10-$G$4)*(A10-$G$4) -> 3417.4452 | E10: 0.99 | F10: 2.579 | G10: =$G$13*F10 -> 26.150019 | I10: =K10-G10 -> 252.78213 | J10: < | K10: =$G$4 -> 278.93215 | L10: < | M10: =K10+G10 -> 305.08217 | O10: =(P10-G10)/G10 -> -0.02537179 | P10: ='300'!G10 -> 25.486546
A11: 681.11685 | B11: =(A11-$G$4)*(A11-$G$4) -> 161752.53 | E11: относ отклонение (относ 300)
A12: 254.7299 | B12: =(A12-$G$4)*(A12-$G$4) -> 585.74897
A13: 235.08798 | B13: =(A13-$G$4)*(A13-$G$4) -> 1922.3112 | E13: sigma_m | G13: =SQRT(G5/G2) -> 10.139596
A14: 121.42863 | B14: =(A14-$G$4)*(A14-$G$4) -> 24807.36
A15: 105.02894 | B15: =(A15-$G$4)*(A15-$G$4) -> 30242.327
A16: 443.5748 | B16: =(A16-$G$4)*(A16-$G$4) -> 27107.201
A17: 267.03747 | B17: =(A17-$G$4)*(A17-$G$4) -> 141.48351
A18: 401.70769 | B18: =(A18-$G$4)*(A18-$G$4) -> 15073.833 | G18: =_xlfn.CONFIDENCE.T(0.01,G6,G3) -> 26.285604 | H18: =G18/G13 -> 2.5923719
A19: 59.379924 | B19: =(A19-$G$4)*(A19-$G$4) -> 48203.181
A20: 774.96764 | B20: =(A20-$G$4)*(A20-$G$4) -> 246051.2
A21: 169.47109 | B21: =(A21-$G$4)*(A21-$G$4) -> 11981.725
A22: 615.23665 | B22: =(A22-$G$4)*(A22-$G$4) -> 113100.71
A23: 80.79866 | B23: =(A23-$G$4)*(A23-$G$4) -> 39256.881
A24: 368.01975 | B24: =(A24-$G$4)*(A24-$G$4) -> 7936.6006
A25: 259.37419 | B25: =(A25-$G$4)*(A25-$G$4) -> 382.51377
A26: 164.98614 | B26: =(A26-$G$4)*(A26-$G$4) -> 12983.693
A27: 326.93469 | B27: =(A27-$G$4)*(A27-$G$4) -> 2304.2431
A28: 594.28892 | B28: =(A28-$G$4)*(A28-$G$4) -> 99449.887
A29: 67.642177 | B29: =(A29-$G$4)*(A29-$G$4) -> 44643.454
A30: 327.53881 | B30: =(A30-$G$4)*(A30-$G$4) -> 2362.6066
... A301: 218.61941 | B301: =(A301-$G$4)*(A301-$G$4) -> 3637.6276

Sheet ген
A1: 209.52881 | C1: 1 | D1: 2 | E1: 3 | F1: 4 | G1: 5 | H1: 6 | I1: 7 | J1: 8 | K1: 9 | L1: 10 | M1: 11 | N1: 12 | O1: 13 | P1: 14 | Q1: 15 | R1: 16 | S1: 17 | T1: 18
A2: 234.92815 | B2: левая | C2: =C8 -> 24.12892 | D2: =C3 -> 78.912131 | E2: =D3 -> 133.69534 | F2: =E3 -> 188.47855 | G2: =F3 -> 243.26176 | H2: =G3 -> 298.04497 | I2: =H3 -> 352.82818 | J2: =I3 -> 407.61139 | K2: =J3 -> 462.3946 | ... T2: =S3 -> 955.4435
A3: 70.260556 | B3: правая | C3: =C2+$E$9 -> 78.912131 | D3: =D2+$E$9 -> 133.69534 | E3: =E2+$E$9 -> 188.47855 | F3: =F2+$E$9 -> 243.26176 | G3: =G2+$E$9 -> 298.04497 | H3: =H2+$E$9 -> 352.82818 | I3: =I2+$E$9 -> 407.61139 | J3: =J2+$E$9 -> 462.3946 | ... T3: =T2+$E$9 -> 1010.2267
A4: 369.86282 | B4: частота | C4: =COUNTIFS($A:$A, ">="&C2, $A:$A, "<="&C3) -> 26 | D4: =COUNTIFS($A:$A, ">="&D2, $A:$A, "<="&D3) -> 36 | E4: =COUNTIFS($A:$A, ">="&E2, $A:$A, "<="&E3) -> 49 | F4: =COUNTIFS($A:$A, ">="&F2, $A:$A, "<="&F3) -> 39 | G4: =COUNTIFS($A:$A, ">="&G2, $A:$A, "<="&G3) -> 39 | H4: =COUNTIFS($A:$A, ">="&H2, $A:$A, "<="&H3) -> 25 | I4: =COUNTIFS($A:$A, ">="&I2, $A:$A, "<="&I3) -> 18 | J4: =COUNTIFS($A:$A, ">="&J2, $A:$A, "<="&J3) -> 19 | ... T4: =COUNTIFS($A:$A, ">="&T2, $A:$A, "<="&T3) -> 2
A5: 332.22945
A6: 130.66505
A7: 107.26249
A8: 304.89436 | C8: =MIN(A:A) -> 24.12892 | E8: =C9-C8 -> 986.09779
A9: 220.47323 | C9: =MAX(A:A) -> 1010.2267 | D9: шаг | E9: =E8/18 -> 54.783211
A10: 681.11685
A11: 254.7299 | C11: =ROUND(C2,2) & "; " & ROUND(C3,2) -> 24.13; 78.91 | D11: =ROUND(D2,2) & "; " & ROUND(D3,2) -> 78.91; 133.7 | E11: =ROUND(E2,2) & "; " & ROUND(E3,2) -> 133.7; 188.48 | F11: =ROUND(F2,2) & "; " & ROUND(F3,2) -> 188.48; 243.26 | G11: =ROUND(G2,2) & "; " & ROUND(G3,2) -> 243.26; 298.04 | H11: =ROUND(H2,2) & "; " & ROUND(H3,2) -> 298.04; 352.83 | I11: =ROUND(I2,2) & "; " & ROUND(I3,2) -> 352.83; 407.61 | J11: =ROUND(J2,2) & "; " & ROUND(J3,2) -> 407.61; 462.39 | ... T11: =ROUND(T2,2) & "; " & ROUND(T3,2) -> 955.44; 1010.23
A12: 235.08798 | C12: 26 | D12: 36 | E12: 49 | F12: 39 | G12: 39 | H12: 25 | I12: 18 | J12: 19 | K12: 23 | L12: 8 | M12: 6 | N12: 3 | O12: 3 | P12: 3 | Q12: 0 | R12: 0 | S12: 1 | T12: 2
A13: 121.42863
A14: 105.02894
A15: 443.5748
A16: 267.03747
A17: 401.70769
A18: 59.379924
A19: 774.96764
A20: 169.47109
A21: 615.23665
A22: 80.79866
A23: 368.01975
A24: 259.37419
... A33: 90.522744
A34: 372.04227 | P34: ВАЩЕ ЖЕСТЬ ПОХОЖЕ!!!
A35: 234.50838
A36: 271.38612
A37: 276.61619
A38: 305.02363 | C38: 24.12892 | D38: 78.912131 | E38: 133.69534 | F38: 188.47855 | G38: 243.26176 | H38: 298.04497 | I38: 352.82818 | J38: 407.61139 | K38: 462.3946 | L38: 517.17782 | M38: 571.96103 | N38: 626.74424 | O38: 681.52745 | P38: 736.31066 | Q38: 791.09387 | R38: 845.87708 | S38: 900.66029 | T38: 955.4435 | U38: 1010.2267
A39: 132.36814 | C39: =(POWER(0.00944,2.6099)*C38^(2.6099-1)*EXP(-0.00944*C38))/FACT(2.6099-1) -> 0.00069455214 | D39: =(POWER(0.00944,2.6099)*D38^(2.6099-1)*EXP(-0.00944*D38))/FACT(2.6099-1) -> 0.0027897928 | E39: =(POWER(0.00944,2.6099)*E38^(2.6099-1)*EXP(-0.00944*E38))/FACT(2.6099-1) -> 0.0038868508 | F39: =(POWER(0.00944,2.6099)*F38^(2.6099-1)*EXP(-0.00944*F38))/FACT(2.6099-1) -> 0.0040281957 | G39: =(POWER(0.00944,2.6099)*G38^(2.6099-1)*EXP(-0.00944*G38))/FACT(2.6099-1) -> 0.0036216772 | H39: =(POWER(0.00944,2.6099)*H38^(2.6099-1)*EXP(-0.00944*H38))/FACT(2.6099-1) -> 0.002994462 | I39: =(POWER(0.00944,2.6099)*I38^(2.6099-1)*EXP(-0.00944*I38))/FACT(2.6099-1) -> 0.0023425978 | J39: =(POWER(0.00944,2.6099)*J38^(2.6099-1)*EXP(-0.00944*J38))/FACT(2.6099-1) -> 0.0017620339 | ... U39: =(POWER(0.00944,2.6099)*U38^(2.6099-1)*EXP(-0.00944*U38))/FACT(2.6099-1) -> 2.5705529e-05
A40: 315.68166
A41: 190.90806
A42: 169.4968
A43: 387.44213
A44: 482.23772
A45: 169.89721
A46: 169.24971
A47: 157.80896
A48: 234.48901
...

Sheet 300
C1: x - m_volna ^ 2
A2: 107.28158 | B2: =(A2-$G$4)*(A2-$G$4) -> 28627.496 | F2: t_p | G2: =G3 -> 300
A3: 127.82735 | B3: =(A3-$G$4)*(A3-$G$4) -> 22097.075 | E3: кол-во | G3: =COUNT(A:A) -> 300
A4: 408.35467 | B4: =(A4-$G$4)*(A4-$G$4) -> 17391.402 | E4: мат ож | G4: =SUM(A:A)/G2 -> 276.4782
A5: 98.890546 | B5: =(A5-$G$4)*(A5-$G$4) -> 31537.376 | E5: дисперсия | G5: =SUM(B:B)/(G2-1) -> 29298.173
A6: 701.75958 | B6: =(A6-$G$4)*(A6-$G$4) -> 180864.25 | E6: ср кв отклонение | G6: =SQRT(G5) -> 171.16709
A7: 271.81439 | B7: =(A7-$G$4)*(A7-$G$4) -> 21.751109 | E7: коэфф вариации | G7: =G6/G4 -> 0.61909796
A8: 320.49549 | B8: =(A8-$G$4)*(A8-$G$4) -> 1937.5219 | D8: доверительный интервал | E8: 0.9 | F8: 1.684 | G8: =$G$13*F8 -> 16.641855 | I8: =K8-G8 -> 259.83635 | J8: < | K8: =$G$4 -> 276.4782 | L8: < | M8: =K8+G8 -> 293.12006
A9: 248.02335 | B9: =(A9-$G$4)*(A9-$G$4) -> 809.67852 | E9: 0.95 | F9: 1.96 | G9: =$G$13*F9 -> 19.36938 | I9: =K9-G9 -> 257.10882 | J9: < | K9: =$G$4 -> 276.4782 | L9: < | M9: =K9+G9 -> 295.84758
A10: 224.91195 | B10: =(A10-$G$4)*(A10-$G$4) -> 2659.078 | E10: 0.99 | F10: 2.579 | G10: =$G$13*F10 -> 25.486546 | I10: =K10-G10 -> 250.99166 | J10: < | K10: =$G$4 -> 276.4782 | L10: < | M10: =K10+G10 -> 301.96475
A11: 454.21521 | B11: =(A11-$G$4)*(A11-$G$4) -> 31590.444 | E11: относ отклонение (относ 300)
A12: 254.47078 | B12: =(A12-$G$4)*(A12-$G$4) -> 484.32669
A13: 216.90658 | B13: =(A13-$G$4)*(A13-$G$4) -> 3548.7783 | E13: sigma_m | G13: =SQRT(G5/G2) -> 9.8823366
A14: 797.62537 | B14: =(A14-$G$4)*(A14-$G$4) -> 271594.37
A15: 630.3531 | B15: =(A15-$G$4)*(A15-$G$4) -> 125227.44
A16: 187.66933 | B16: =(A16-$G$4)*(A16-$G$4) -> 7887.0151
A17: 81.610534 | B17: =(A17-$G$4)*(A17-$G$4) -> 37973.408
A18: 283.24937 | B18: =(A18-$G$4)*(A18-$G$4) -> 45.848656 | G18: =_xlfn.CONFIDENCE.T(0.01,G6,G3) -> 25.618692 | H18: =G18/G13 -> 2.5923719
A19: 151.51033 | B19: =(A19-$G$4)*(A19-$G$4) -> 15616.969
A20: 407.89408 | B20: =(A20-$G$4)*(A20-$G$4) -> 17270.133
A21: 196.50013 | B21: =(A21-$G$4)*(A21-$G$4) -> 6396.4928
A22: 226.1019 | B22: =(A22-$G$4)*(A22-$G$4) -> 2537.7718
A23: 296.82007 | B23: =(A23-$G$4)*(A23-$G$4) -> 413.79145
A24: 365.89968 | B24: =(A24-$G$4)*(A24-$G$4) -> 7996.2004
A25: 126.08794 | B25: =(A25-$G$4)*(A25-$G$4) -> 22617.231
A26: 158.17331 | B26: =(A26-$G$4)*(A26-$G$4) -> 13996.047
A27: 169.31815 | B27: =(A27-$G$4)*(A27-$G$4) -> 11483.278
A28: 356.99176 | B28: =(A28-$G$4)*(A28-$G$4) -> 6482.4332
A29: 51.531821 | B29: =(A29-$G$4)*(A29-$G$4) -> 50600.875
A30: 138.94007 | B30: =(A30-$G$4)*(A30-$G$4) -> 18916.738
... A301: 218.61941 | B301: =(A301-$G$4)*(A301-$G$4) -> 3347.6403

Sheet 200
C1: x - m_volna ^ 2
A2: 107.28158 | B2: =(A2-$G$4)*(A2-$G$4) -> 24903.048 | F2: t_p | G2: =G3 -> 200 | O2: Отклонение от эталона
A3: 127.82735 | B3: =(A3-$G$4)*(A3-$G$4) -> 18840.644 | E3: кол-во | G3: =COUNT(A:A) -> 200
A4: 408.35467 | B4: =(A4-$G$4)*(A4-$G$4) -> 20525.172 | E4: мат ож | G4: =SUM(A:A)/G2 -> 265.08858 | O4: =(P4-G4)/G4 -> 0.042965349 | P4: ='300'!G4 -> 276.4782
A5: 98.890546 | B5: =(A5-$G$4)*(A5-$G$4) -> 27621.786 | E5: дисперсия | G5: =SUM(B:B)/(G2-1) -> 24872.852 | O5: =(P5-G5)/G5 -> 0.17791773 | P5: ='300'!G5 -> 29298.173
A6: 701.75958 | B6: =(A6-$G$4)*(A6-$G$4) -> 190681.56 | E6: ср кв отклонение | G6: =SQRT(G5) -> 157.71129 | O6: =(P6-G6)/G6 -> 0.085319184 | P6: ='300'!G6 -> 171.16709
A7: 271.81439 | B7: =(A7-$G$4)*(A7-$G$4) -> 45.236584 | E7: коэфф вариации | G7: =G6/G4 -> 0.59493809 | O7: =(P7-G7)/G7 -> 0.040609053 | P7: ='300'!G7 -> 0.61909796
A8: 320.49549 | B8: =(A8-$G$4)*(A8-$G$4) -> 3069.9262 | D8: доверительный интервал | E8: 0.9 | F8: 1.684 | G8: =$G$13*F8 -> 18.779753 | I8: =K8-G8 -> 246.30883 | J8: < | K8: =$G$4 -> 265.08858 | L8: < | M8: =K8+G8 -> 283.86833 | O8: =(P8-G8)/G8 -> -0.1138406 | P8: ='300'!G8 -> 16.641855
A9: 248.02335 | B9: =(A9-$G$4)*(A9-$G$4) -> 291.22199 | E9: 0.95 | F9: 1.96 | G9: =$G$13*F9 -> 21.85767 | I9: =K9-G9 -> 243.23091 | J9: < | K9: =$G$4 -> 265.08858 | L9: < | M9: =K9+G9 -> 286.94625 | O9: =(P9-G9)/G9 -> -0.1138406 | P9: ='300'!G9 -> 19.36938
A10: 224.91195 | B10: =(A10-$G$4)*(A10-$G$4) -> 1614.1612 | E10: 0.99 | F10: 2.579 | G10: =$G$13*F10 -> 28.760679 | I10: =K10-G10 -> 236.3279 | J10: < | K10: =$G$4 -> 265.08858 | L10: < | M10: =K10+G10 -> 293.84926 | O10: =(P10-G10)/G10 -> -0.1138406 | P10: ='300'!G10 -> 25.486546
A11: 454.21521 | B11: =(A11-$G$4)*(A11-$G$4) -> 35768.883 | E11: относ отклонение (относ 300)
A12: 254.47078 | B12: =(A12-$G$4)*(A12-$G$4) -> 112.73768
A13: 216.90658 | B13: =(A13-$G$4)*(A13-$G$4) -> 2321.5051 | E13: sigma_m | G13: =SQRT(G5/G2) -> 11.151872
A14: 797.62537 | B14: =(A14-$G$4)*(A14-$G$4) -> 283595.44
A15: 630.3531 | B15: =(A15-$G$4)*(A15-$G$4) -> 133418.17
A16: 187.66933 | B16: =(A16-$G$4)*(A16-$G$4) -> 5993.7395
A17: 81.610534 | B17: =(A17-$G$4)*(A17-$G$4) -> 33664.193
A18: 283.24937 | B18: =(A18-$G$4)*(A18-$G$4) -> 329.81418
A19: 151.51033 | B19: =(A19-$G$4)*(A19-$G$4) -> 12900.018
A20: 407.89408 | B20: =(A20-$G$4)*(A20-$G$4) -> 20393.411
A21: 196.50013 | B21: =(A21-$G$4)*(A21-$G$4) -> 4704.376
A22: 226.1019 | B22: =(A22-$G$4)*(A22-$G$4) -> 1519.9611
A23: 296.82007 | B23: =(A23-$G$4)*(A23-$G$4) -> 1006.8873
A24: 365.89968 | B24: =(A24-$G$4)*(A24-$G$4) -> 10162.878
A25: 126.08794 | B25: =(A25-$G$4)*(A25-$G$4) -> 19321.178
... A201: 90.023264 | B201: =(A201-$G$4)*(A201-$G$4) -> 30647.865

Sheet 100
C1: x - m_volna ^ 2
A2: 107.28158 | B2: =(A2-$G$4)*(A2-$G$4) -> 28784.491 | F2: t_p | G2: =G3 -> 100 | O2: Отклонение от эталона
A3: 127.82735 | B3: =(A3-$G$4)*(A3-$G$4) -> 22235.032 | E3: кол-во | G3: =COUNT(A:A) -> 100
A4: 408.35467 | B4: =(A4-$G$4)*(A4-$G$4) -> 17269.418 | E4: мат ож | G4: =SUM(A:A)/G2 -> 276.94151 | O4: =(P4-G4)/G4 -> -0.0016729467 | P4: ='300'!G4 -> 276.4782
A5: 98.890546 | B5: =(A5-$G$4)*(A5-$G$4) -> 31702.146 | E5: дисперсия | G5: =SUM(B:B)/(G2-1) -> 25957.93 | O5: =(P5-G5)/G5 -> 0.1286791 | P5: ='300'!G5 -> 29298.173
A6: 701.75958 | B6: =(A6-$G$4)*(A6-$G$4) -> 180470.39 | E6: ср кв отклонение | G6: =SQRT(G5) -> 161.11465 | O6: =(P6-G6)/G6 -> 0.062393099 | P6: ='300'!G6 -> 171.16709
A7: 271.81439 | B7: =(A7-$G$4)*(A7-$G$4) -> 26.287327 | E7: коэфф вариации | G7: =G6/G4 -> 0.58176417 | O7: =(P7-G7)/G7 -> 0.064173405 | P7: ='300'!G7 -> 0.61909796
A8: 320.49549 | B8: =(A8-$G$4)*(A8-$G$4) -> 1896.9494 | D8: доверительный интервал | E8: 0.9 | F8: 1.684 | G8: =$G$13*F8 -> 27.131707 | I8: =K8-G8 -> 249.8098 | J8: < | K8: =$G$4 -> 276.94151 | L8: < | M8: =K8+G8 -> 304.07322 | O8: =(P8-G8)/G8 -> -0.38662706 | P8: ='300'!G8 -> 16.641855
A9: 248.02335 | B9: =(A9-$G$4)*(A9-$G$4) -> 836.25992 | E9: 0.95 | F9: 1.96 | G9: =$G$13*F9 -> 31.578471 | I9: =K9-G9 -> 245.36304 | J9: < | K9: =$G$4 -> 276.94151 | L9: < | M9: =K9+G9 -> 308.51998 | O9: =(P9-G9)/G9 -> -0.38662706 | P9: ='300'!G9 -> 19.36938
A10: 224.91195 | B10: =(A10-$G$4)*(A10-$G$4) -> 2707.0748 | E10: 0.99 | F10: 2.579 | G10: =$G$13*F10 -> 41.551468 | I10: =K10-G10 -> 235.39004 | J10: < | K10: =$G$4 -> 276.94151 | L10: < | M10: =K10+G10 -> 318.49298 | O10: =(P10-G10)/G10 -> -0.38662706 | P10: ='300'!G10 -> 25.486546
A11: 454.21521 | B11: =(A11-$G$4)*(A11-$G$4) -> 31425.965 | E11: относ отклонение (относ 300)
A12: 254.47078 | B12: =(A12-$G$4)*(A12-$G$4) -> 504.93379
A13: 216.90658 | B13: =(A13-$G$4)*(A13-$G$4) -> 3604.193 | E13: sigma_m | G13: =SQRT(G5/G2) -> 16.111465
A14: 797.62537 | B14: =(A14-$G$4)*(A14-$G$4) -> 271111.68
A15: 630.3531 | B15: =(A15-$G$4)*(A15-$G$4) -> 124899.75
A16: 187.66933 | B16: =(A16-$G$4)*(A16-$G$4) -> 7969.5215
A17: 81.610534 | B17: =(A17-$G$4)*(A17-$G$4) -> 38154.191
A18: 283.24937 | B18: =(A18-$G$4)*(A18-$G$4) -> 39.789037
A19: 151.51033 | B19: =(A19-$G$4)*(A19-$G$4) -> 15732.981
A20: 407.89408 | B20: =(A20-$G$4)*(A20-$G$4) -> 17148.575
A21: 196.50013 | B21: =(A21-$G$4)*(A21-$G$4) -> 6470.8165
A22: 226.1019 | B22: =(A22-$G$4)*(A22-$G$4) -> 2584.666
A23: 296.82007 | B23: =(A23-$G$4)*(A23-$G$4) -> 395.15699
A24: 365.89968 | B24: =(A24-$G$4)*(A24-$G$4) -> 7913.5556
A25: 126.08794 | B25: =(A25-$G$4)*(A25-$G$4) -> 22756.8
... A101: 102.97002 | B101: =(A101-$G$4)*(A101-$G$4) -> 30266.08

Sheet 50
C1: x - m_volna ^ 2
A2: 107.28158 | B2: =(A2-$G$4)*(A2-$G$4) -> 27071.521 | F2: t_p | G2: 50 | O2: Отклонение от эталона
A3: 127.82735 | B3: =(A3-$G$4)*(A3-$G$4) -> 20732.684 | E3: кол-во | G3: =COUNT(A:A) -> 50
A4: 408.35467 | B4: =(A4-$G$4)*(A4-$G$4) -> 18642.852 | E4: мат ож | G4: =SUM(A:A)/G2 -> 271.81584 | O4: =(P4-G4)/G4 -> 0.017152652 | P4: ='300'!G4 -> 276.4782
A5: 98.890546 | B5: =(A5-$G$4)*(A5-$G$4) -> 29903.157 | E5: дисперсия | G5: =SUM(B:B)/(G2-1) -> 25163.665 | O5: =(P5-G5)/G5 -> 0.16430468 | P5: ='300'!G5 -> 29298.173
A6: 701.75958 | B6: =(A6-$G$4)*(A6-$G$4) -> 184851.62 | E6: ср кв отклонение | G6: =SQRT(G5) -> 158.63059 | O6: =(P6-G6)/G6 -> 0.079029508 | P6: ='300'!G6 -> 171.16709
A7: 271.81439 | B7: =(A7-$G$4)*(A7-$G$4) -> 2.0910405e-06 | E7: коэфф вариации | G7: =G6/G4 -> 0.58359584 | O7: =(P7-G7)/G7 -> 0.060833402 | P7: ='300'!G7 -> 0.61909796
A8: 320.49549 | B8: =(A8-$G$4)*(A8-$G$4) -> 2369.7087 | D8: доверительный интервал | E8: 0.9 | F8: 1.684 | G8: =$G$13*F8 -> 37.778441 | I8: =K8-G8 -> 234.0374 | J8: < | K8: =$G$4 -> 271.81584 | L8: < | M8: =K8+G8 -> 309.59428 | O8: =(P8-G8)/G8 -> -0.55948805 | P8: ='300'!G8 -> 16.641855
A9: 248.02335 | B9: =(A9-$G$4)*(A9-$G$4) -> 566.0825 | E9: 0.95 | F9: 1.96 | G9: =$G$13*F9 -> 43.970157 | I9: =K9-G9 -> 227.84568 | J9: < | K9: =$G$4 -> 271.81584 | L9: < | M9: =K9+G9 -> 315.786 | O9: =(P9-G9)/G9 -> -0.55948805 | P9: ='300'!G9 -> 19.36938
A10: 224.91195 | B10: =(A10-$G$4)*(A10-$G$4) -> 2199.9746 | E10: 0.99 | F10: 2.579 | G10: =$G$13*F10 -> 57.856651 | I10: =K10-G10 -> 213.95919 | J10: < | K10: =$G$4 -> 271.81584 | L10: < | M10: =K10+G10 -> 329.67249 | O10: =(P10-G10)/G10 -> -0.55948805 | P10: ='300'!G10 -> 25.486546
A11: 454.21521 | B11: =(A11-$G$4)*(A11-$G$4) -> 33269.531 | E11: относ отклонение (относ 300)
A12: 254.47078 | B12: =(A12-$G$4)*(A12-$G$4) -> 300.85115
A13: 216.90658 | B13: =(A13-$G$4)*(A13-$G$4) -> 3015.0269 | E13: sigma_m | G13: =SQRT(G5/G2) -> 22.433754
A14: 797.62537 | B14: =(A14-$G$4)*(A14-$G$4) -> 276475.67
A15: 630.3531 | B15: =(A15-$G$4)*(A15-$G$4) -> 128548.97
A16: 187.66933 | B16: =(A16-$G$4)*(A16-$G$4) -> 7080.6344
A17: 81.610534 | B17: =(A17-$G$4)*(A17-$G$4) -> 36178.059
A18: 283.24937 | B18: =(A18-$G$4)*(A18-$G$4) -> 130.72552
A19: 151.51033 | B19: =(A19-$G$4)*(A19-$G$4) -> 14473.415
A20: 407.89408 | B20: =(A20-$G$4)*(A20-$G$4) -> 18517.287
A21: 196.50013 | B21: =(A21-$G$4)*(A21-$G$4) -> 5672.4569
A22: 226.1019 | B22: =(A22-$G$4)*(A22-$G$4) -> 2089.7643
A23: 296.82007 | B23: =(A23-$G$4)*(A23-$G$4) -> 625.21136
A24: 365.89968 | B24: =(A24-$G$4)*(A24-$G$4) -> 8851.7687
A25: 126.08794 | B25: =(A25-$G$4)*(A25-$G$4) -> 21236.621
... A51: 184.10638 | B51: =(A51-$G$4)*(A51-$G$4) -> 7692.95

Sheet 20
C1: x - m_volna ^ 2
A2: 107.28158 | B2: =(A2-$G$4)*(A2-$G$4) -> 40516.296 | F2: t_p | G2: 20 | O2: Отклонение от эталона
A3: 127.82735 | B3: =(A3-$G$4)*(A3-$G$4) -> 32667.249 | E3: кол-во | G3: =COUNT(A:A) -> 20
A4: 408.35467 | B4: =(A4-$G$4)*(A4-$G$4) -> 9957.342 | E4: мат ож | G4: =SUM(A:A)/G2 -> 308.56819 | O4: =(P4-G4)/G4 -> -0.10399641 | P4: ='300'!G4 -> 276.4782
A5: 98.890546 | B5: =(A5-$G$4)*(A5-$G$4) -> 43964.713 | E5: дисперсия | G5: =SUM(B:B)/(G2-1) -> 41209.764 | O5: =(P5-G5)/G5 -> -0.28904778 | P5: ='300'!G5 -> 29298.173
A6: 701.75958 | B6: =(A6-$G$4)*(A6-$G$4) -> 154599.47 | E6: ср кв отклонение | G6: =SQRT(G5) -> 203.00188 | O6: =(P6-G6)/G6 -> -0.15682018 | P6: ='300'!G6 -> 171.16709
A7: 271.81439 | B7: =(A7-$G$4)*(A7-$G$4) -> 1350.8413 | E7: коэфф вариации | G7: =G6/G4 -> 0.65788338 | O7: =(P7-G7)/G7 -> -0.058954857 | P7: ='300'!G7 -> 0.61909796
A8: 320.49549 | B8: =(A8-$G$4)*(A8-$G$4) -> 142.26064 | D8: доверительный интервал | E8: 0.9 | F8: 1.684 | G8: =$G$13*F8 -> 76.44114 | I8: =K8-G8 -> 232.12705 | J8: < | K8: =$G$4 -> 308.56819 | L8: < | M8: =K8+G8 -> 385.00933 | O8: =(P8-G8)/G8 -> -0.78229191 | P8: ='300'!G8 -> 16.641855
A9: 248.02335 | B9: =(A9-$G$4)*(A9-$G$4) -> 3665.677 | E9: 0.95 | F9: 1.96 | G9: =$G$13*F9 -> 88.969497 | I9: =K9-G9 -> 219.59869 | J9: < | K9: =$G$4 -> 308.56819 | L9: < | M9: =K9+G9 -> 397.53768 | O9: =(P9-G9)/G9 -> -0.78229191 | P9: ='300'!G9 -> 19.36938
A10: 224.91195 | B10: =(A10-$G$4)*(A10-$G$4) -> 6998.3653 | E10: 0.99 | F10: 2.579 | G10: =$G$13*F10 -> 117.06752 | I10: =K10-G10 -> 191.50067 | J10: < | K10: =$G$4 -> 308.56819 | L10: < | M10: =K10+G10 -> 425.6357 | O10: =(P10-G10)/G10 -> -0.78229191 | P10: ='300'!G10 -> 25.486546
A11: 454.21521 | B11: =(A11-$G$4)*(A11-$G$4) -> 21213.056 | E11: относ отклонение (относ 300)
A12: 254.47078 | B12: =(A12-$G$4)*(A12-$G$4) -> 2926.5295
A13: 216.90658 | B13: =(A13-$G$4)*(A13-$G$4) -> 8401.8503 | E13: sigma_m | G13: =SQRT(G5/G2) -> 45.392601
A14: 797.62537 | B14: =(A14-$G$4)*(A14-$G$4) -> 239176.93
A15: 630.3531 | B15: =(A15-$G$4)*(A15-$G$4) -> 103545.53
A16: 187.66933 | B16: =(A16-$G$4)*(A16-$G$4) -> 14616.533
A17: 81.610534 | B17: =(A17-$G$4)*(A17-$G$4) -> 51509.776
A18: 283.24937 | B18: =(A18-$G$4)*(A18-$G$4) -> 641.04269
A19: 151.51033 | B19: =(A19-$G$4)*(A19-$G$4) -> 24667.17
A20: 407.89408 | B20: =(A20-$G$4)*(A20-$G$4) -> 9865.6331
A21: 196.50013 | B21: =(A21-$G$4)*(A21-$G$4) -> 12559.25

Sheet 10
B1: x - m_volna ^ 2
A2: 107.28158 | B2: =(A2-$G$4)*(A2-$G$4) -> 35749.669 | F2: t_p | G2: 10 | O2: Отклонение от эталона
A3: 127.82735 | B3: =(A3-$G$4)*(A3-$G$4) -> 28402.381 | E3: кол-во | G3: =COUNT(A2:A11) -> 10
A4: 408.35467 | B4: =(A4-$G$4)*(A4-$G$4) -> 12543.385 | E4: мат ож | G4: =SUM(A2:A11)/G2 -> 296.35741 | O4: =(P4-G4)/G4 -> -0.067078501 | P4: ='300'!G4 -> 276.4782
A5: 98.890546 | B5: =(A5-$G$4)*(A5-$G$4) -> 38993.164 | E5: дисперсия | G5: =SUM(B2:B11)/(G2-1) -> 34842.693 | O5: =(P5-G5)/G5 -> -0.15913007 | P5: ='300'!G5 -> 29298.173
A6: 701.75958 | B6: =(A6-$G$4)*(A6-$G$4) -> 164350.91 | E6: ср кв отклонение | G6: =SQRT(G5) -> 186.66198 | O6: =(P6-G6)/G6 -> -0.083010399 | P6: ='300'!G6 -> 171.16709
A7: 271.81439 | B7: =(A7-$G$4)*(A7-$G$4) -> 602.3598 | E7: коэфф вариации | G7: =G6/G4 -> 0.62985425 | O7: =(P7-G7)/G7 -> -0.017077426 | P7: ='300'!G7 -> 0.61909796
A8: 320.49549 | B8: =(A8-$G$4)*(A8-$G$4) -> 582.64691 | D8: доверительный интервал | E8: 0.9 | F8: 1.684 | G8: =$G$13*F8 -> 99.402646 | I8: =K8-G8 -> 196.95477 | J8: < | K8: =$G$4 -> 296.35741 | L8: < | M8: =K8+G8 -> 395.76006 | O8: =(P8-G8)/G8 -> -0.83258137 | P8: ='300'!G8 -> 16.641855
A9: 248.02335 | B9: =(A9-$G$4)*(A9-$G$4) -> 2336.1815 | E9: 0.95 | F9: 1.96 | G9: =$G$13*F9 -> 115.69429 | I9: =K9-G9 -> 180.66312 | J9: < | K9: =$G$4 -> 296.35741 | L9: < | M9: =K9+G9 -> 412.0517 | O9: =(P9-G9)/G9 -> -0.83258137 | P9: ='300'!G9 -> 19.36938
A10: 224.91195 | B10: =(A10-$G$4)*(A10-$G$4) -> 5104.4537 | E10: 0.99 | F10: 2.579 | G10: =$G$13*F10 -> 152.23244 | I10: =K10-G10 -> 144.12498 | J10: < | K10: =$G$4 -> 296.35741 | L10: < | M10: =K10+G10 -> 448.58985 | O10: =(P10-G10)/G10 -> -0.83258137 | P10: ='300'!G10 -> 25.486546
A11: 454.21521 | B11: =(A11-$G$4)*(A11-$G$4) -> 24919.084 | E11: относ отклонение (относ 300)
E13: sigma_m | G13: =SQRT(G5/G2) -> 59.0277

Sheet Лист1
S1: =CORREL($Q$4:$Q$303,S4:S303) -> -0.031988355 | T1: =CORREL($Q$4:$Q$303,T4:T303) -> -0.030426633 | U1: =CORREL($Q$4:$Q$303,U4:U303) -> -0.049195743 | V1: =CORREL($Q$4:$Q$303,V4:V303) -> 0.0042372883 | W1: =CORREL($Q$4:$Q$303,W4:W303) -> 0.029058435 | X1: =CORREL($Q$4:$Q$303,X4:X303) -> 0.068666816 | Y1: =CORREL($Q$4:$Q$303,Y4:Y303) -> 0.011581391 | Z1: =CORREL($Q$4:$Q$303,Z4:Z303) -> 0.058080889 | ... AG1: =CORREL($Q$4:$Q$303,AG4:AG303) -> 0.0077740053 | AJ1: =AVERAGE(S1:AG1) -> 0.0028857378
AJ2: =MEDIAN(S1:AG1) -> 0.0042372883
R3: x - m | S3: 1 | T3: 2 | U3: 3 | V3: 4 | W3: 5 | X3: 6 | Y3: 7 | Z3: 8 | AA3: 9 | AB3: 10 | AC3: 11 | AD3: 12 | AE3: 13 | AF3: 14 | AG3: 15
A4: 107.28158 | Q4: 107.28158 | R4: =Q4-$F$30 -> -169.19662 | S4: =Q5 -> 127.82735 | T4: =S5 -> 408.35467 | U4: =T5 -> 98.890546 | V4: =U5 -> 701.75958 | W4: =V5 -> 271.81439 | X4: =W5 -> 320.49549 | Y4: =X5 -> 248.02335 | Z4: =Y5 -> 224.91195 | AA4: =Z5 -> 454.21521 | ... AG4: =AF5 -> 81.610534
A5: 127.82735 | Q5: 127.82735 | R5: =Q5-$F$30 -> -148.65085 | S5: =Q6 -> 408.35467 | T5: =S6 -> 98.890546 | U5: =T6 -> 701.75958 | V5: =U6 -> 271.81439 | W5: =V6 -> 320.49549 | X5: =W6 -> 248.02335 | Y5: =X6 -> 224.91195 | Z5: =Y6 -> 454.21521 | AA5: =Z6 -> 254.47078 | ... AG5: =AF6 -> 283.24937
A6: 408.35467 | Q6: 408.35467 | R6: =Q6-$F$30 -> 131.87647 | S6: =Q7 -> 98.890546 | T6: =S7 -> 701.75958 | U6: =T7 -> 271.81439 | V6: =U7 -> 320.49549 | W6: =V7 -> 248.02335 | X6: =W7 -> 224.91195 | Y6: =X7 -> 454.21521 | Z6: =Y7 -> 254.47078 | AA6: =Z7 -> 216.90658 | ... AG6: =AF7 -> 151.51033
A7: 98.890546 | Q7: 98.890546 | R7: =Q7-$F$30 -> -177.58766 | S7: =Q8 -> 701.75958 | T7: =S8 -> 271.81439 | U7: =T8 -> 320.49549 | V7: =U8 -> 248.02335 | W7: =V8 -> 224.91195 | X7: =W8 -> 454.21521 | Y7: =X8 -> 254.47078 | Z7: =Y8 -> 216.90658 | AA7: =Z8 -> 797.62537 | ... AG7: =AF8 -> 407.89408
A8: 701.75958 | Q8: 701.75958 | R8: =Q8-$F$30 -> 425.28138 | S8: =Q9 -> 271.81439 | T8: =S9 -> 320.49549 | U8: =T9 -> 248.02335 | V8: =U9 -> 224.91195 | W8: =V9 -> 454.21521 | X8: =W9 -> 254.47078 | Y8: =X9 -> 216.90658 | Z8: =Y9 -> 797.62537 | AA8: =Z9 -> 630.3531 | ... AG8: =AF9 -> 196.50013
A9: 271.81439 | Q9: 271.81439 | R9: =Q9-$F$30 -> -4.6638084 | S9: =Q10 -> 320.49549 | T9: =S10 -> 248.02335 | U9: =T10 -> 224.91195 | V9: =U10 -> 454.21521 | W9: =V10 -> 254.47078 | X9: =W10 -> 216.90658 | Y9: =X10 -> 797.62537 | Z9: =Y10 -> 630.3531 | AA9: =Z10 -> 187.66933 | ... AG9: =AF10 -> 226.1019
A10: 320.49549 | Q10: 320.49549 | R10: =Q10-$F$30 -> 44.017291 | S10: =Q11 -> 248.02335 | T10: =S11 -> 224.91195 | U10: =T11 -> 454.21521 | V10: =U11 -> 254.47078 | W10: =V11 -> 216.90658 | X10: =W11 -> 797.62537 | Y10: =X11 -> 630.3531 | Z10: =Y11 -> 187.66933 | AA10: =Z11 -> 81.610534 | ... AG10: =AF11 -> 296.82007
A11: 248.02335 | Q11: 248.02335 | R11: =Q11-$F$30 -> -28.454851 | S11: =Q12 -> 224.91195 | T11: =S12 -> 454.21521 | U11: =T12 -> 254.47078 | V11: =U12 -> 216.90658 | W11: =V12 -> 797.62537 | X11: =W12 -> 630.3531 | Y11: =X12 -> 187.66933 | Z11: =Y12 -> 81.610534 | AA11: =Z12 -> 283.24937 | ... AG11: =AF12 -> 365.89968
A12: 224.91195 | Q12: 224.91195 | R12: =Q12-$F$30 -> -51.566249 | S12: =Q13 -> 454.21521 | T12: =S13 -> 254.47078 | U12: =T13 -> 216.90658 | V12: =U13 -> 797.62537 | W12: =V13 -> 630.3531 | X12: =W13 -> 187.66933 | Y12: =X13 -> 81.610534 | Z12: =Y13 -> 283.24937 | AA12: =Z13 -> 151.51033 | ... AG12: =AF13 -> 126.08794
A13: 454.21521 | Q13: 454.21521 | R13: =Q13-$F$30 -> 177.73701 | S13: =Q14 -> 254.47078 | T13: =S14 -> 216.90658 | U13: =T14 -> 797.62537 | V13: =U14 -> 630.3531 | W13: =V14 -> 187.66933 | X13: =W14 -> 81.610534 | Y13: =X14 -> 283.24937 | Z13: =Y14 -> 151.51033 | AA13: =Z14 -> 407.89408 | ... AG13: =AF14 -> 158.17331
A14: 254.47078 | Q14: 254.47078 | R14: =Q14-$F$30 -> -22.007424 | S14: =Q15 -> 216.90658 | T14: =S15 -> 797.62537 | U14: =T15 -> 630.3531 | V14: =U15 -> 187.66933 | W14: =V15 -> 81.610534 | X14: =W15 -> 283.24937 | Y14: =X15 -> 151.51033 | Z14: =Y15 -> 407.89408 | AA14: =Z15 -> 196.50013 | ... AG14: =AF15 -> 169.31815
A15: 216.90658 | Q15: 216.90658 | R15: =Q15-$F$30 -> -59.571623 | S15: =Q16 -> 797.62537 | T15: =S16 -> 630.3531 | U15: =T16 -> 187.66933 | V15: =U16 -> 81.610534 | W15: =V16 -> 283.24937 | X15: =W16 -> 151.51033 | Y15: =X16 -> 407.89408 | Z15: =Y16 -> 196.50013 | AA15: =Z16 -> 226.1019 | ... AG15: =AF16 -> 356.99176
... A27: 126.08794 | Q27: 126.08794 | R27: =Q27-$F$30 -> -150.39026 | S27: =Q28 -> 158.17331 | T27: =S28 -> 169.31815 | U27: =T28 -> 356.99176 | V27: =U28 -> 51.531821 | W27: =V28 -> 138.94007 | X27: =W28 -> 122.36436 | Y27: =X28 -> 192.42386 | Z27: =Y28 -> 314.19162 | AA27: =Z28 -> 224.76624 | ... AG27: =AF28 -> 286.74132
A28: 158.17331 | E28: t_p | F28: 300 | Q28: 158.17331 | R28: =Q28-$F$30 -> -118.30489 | S28: =Q29 -> 169.31815 | T28: =S29 -> 356.99176 | U28: =T29 -> 51.531821 | V28: =U29 -> 138.94007 | W28: =V29 -> 122.36436 | X28: =W29 -> 192.42386 | Y28: =X29 -> 314.19162 | Z28: =Y29 -> 224.76624 | AA28: =Z29 -> 55.898927 | ... AG28: =AF29 -> 133.99561
A29: 169.31815 | D29: кол-во | F29: 300 | Q29: 169.31815 | R29: =Q29-$F$30 -> -107.16006 | S29: =Q30 -> 356.99176 | T29: =S30 -> 51.531821 | U29: =T30 -> 138.94007 | V29: =U30 -> 122.36436 | W29: =V30 -> 192.42386 | X29: =W30 -> 314.19162 | Y29: =X30 -> 224.76624 | Z29: =Y30 -> 55.898927 | AA29: =Z30 -> 327.76712 | ... AG29: =AF30 -> 229.31356
A30: 356.99176 | D30: мат ож | F30: 276.4782 | Q30: 356.99176 | R30: =Q30-$F$30 -> 80.513559 | S30: =Q31 -> 51.531821 | T30: =S31 -> 138.94007 | U30: =T31 -> 122.36436 | V30: =U31 -> 192.42386 | W30: =V31 -> 314.19162 | X30: =W31 -> 224.76624 | Y30: =X31 -> 55.898927 | Z30: =Y31 -> 327.76712 | AA30: =Z31 -> 375.33573 | ... AG30: =AF31 -> 427.57965
A31: 51.531821 | D31: дисперсия | F31: 29298.173 | Q31: 51.531821 | R31: =Q31-$F$30 -> -224.94638 | S31: =Q32 -> 138.94007 | T31: =S32 -> 122.36436 | U31: =T32 -> 192.42386 | V31: =U32 -> 314.19162 | W31: =V32 -> 224.76624 | X31: =W32 -> 55.898927 | Y31: =X32 -> 327.76712 | Z31: =Y32 -> 375.33573 | AA31: =Z32 -> 227.86162 | ... AG31: =AF32 -> 379.8838
A32: 138.94007 | D32: ср кв отклонение | F32: 171.16709 | Q32: 138.94007 | R32: =Q32-$F$30 -> -137.53813 | S32: =Q33 -> 122.36436 | T32: =S33 -> 192.42386 | U32: =T33 -> 314.19162 | V32: =U33 -> 224.76624 | W32: =V33 -> 55.898927 | X32: =W33 -> 327.76712 | Y32: =X33 -> 375.33573 | Z32: =Y33 -> 227.86162 | AA32: =Z33 -> 355.13663 | ... AG32: =AF33 -> 470.07277
A33: 122.36436 | D33: коэфф вариации | F33: 0.61909796 | Q33: 122.36436 | R33: =Q33-$F$30 -> -154.11384 | S33: =Q34 -> 192.42386 | T33: =S34 -> 314.19162 | U33: =T34 -> 224.76624 | V33: =U34 -> 55.898927 | W33: =V34 -> 327.76712 | X33: =W34 -> 375.33573 | Y33: =X34 -> 227.86162 | Z33: =Y34 -> 355.13663 | AA33: =Z34 -> 286.74132 | ... AG33: =AF34 -> 270.6898
A34: 192.42386 | C34: доверительный интервал | D34: 0.9 | E34: 1.684 | F34: 16.641855 | H34: 259.83635 | I34: < | J34: 276.4782 | K34: < | L34: 293.12006 | Q34: 192.42386 | R34: =Q34-$F$30 -> -84.054343 | S34: =Q35 -> 314.19162 | T34: =S35 -> 224.76624 | U34: =T35 -> 55.898927 | V34: =U35 -> 327.76712 | W34: =V35 -> 375.33573 | X34: =W35 -> 227.86162 | Y34: =X35 -> 355.13663 | Z34: =Y35 -> 286.74132 | AA34: =Z35 -> 133.99561 | ... AG34: =AF35 -> 151.08022
A35: 314.19162 | D35: 0.95 | E35: 1.96 | F35: 19.36938 | H35: 257.10882 | I35: < | J35: 276.4782 | K35: < | L35: 295.84758 | Q35: 314.19162 | R35: =Q35-$F$30 -> 37.713415 | S35: =Q36 -> 224.76624 | T35: =S36 -> 55.898927 | U35: =T36 -> 327.76712 | V35: =U36 -> 375.33573 | W35: =V36 -> 227.86162 | X35: =W36 -> 355.13663 | Y35: =X36 -> 286.74132 | Z35: =Y36 -> 133.99561 | AA35: =Z36 -> 229.31356 | ... AG35: =AF36 -> 184.74179
A36: 224.76624 | D36: 0.99 | E36: 3.29 | F36: 32.512887 | H36: 243.96531 | I36: < | J36: 276.4782 | K36: < | L36: 308.99109 | Q36: 224.76624 | R36: =Q36-$F$30 -> -51.711963 | S36: =Q37 -> 55.898927 | T36: =S37 -> 327.76712 | U36: =T37 -> 375.33573 | V36: =U37 -> 227.86162 | W36: =V37 -> 355.13663 | X36: =W37 -> 286.74132 | Y36: =X37 -> 133.99561 | Z36: =Y37 -> 229.31356 | AA36: =Z37 -> 427.57965 | ... AG36: =AF37 -> 484.80315
